[0m10:57:34.762527 [debug] [MainThread]: Sending event: {'category': 'dbt', 'action': 'invocation', 'label': 'start', 'context': [<snowplow_tracker.self_describing_json.SelfDescribingJson object at 0x000002391F36C230>, <snowplow_tracker.self_describing_json.SelfDescribingJson object at 0x000002391EF53260>, <snowplow_tracker.self_describing_json.SelfDescribingJson object at 0x000002391F36D790>]}


============================== 10:57:34.778110 | 749d30c2-5127-4dbe-93a3-e0adcf82e190 ==============================
[0m10:57:34.778110 [info ] [MainThread]: Running with dbt=1.9.4
[0m10:57:34.778110 [debug] [MainThread]: running dbt with arguments {'printer_width': '80', 'indirect_selection': 'eager', 'log_cache_events': 'False', 'write_json': 'True', 'partial_parse': 'True', 'cache_selected_only': 'False', 'profiles_dir': 'C:\\Users\\zhma\\.dbt', 'fail_fast': 'False', 'warn_error': 'None', 'log_path': 'logs', 'debug': 'False', 'version_check': 'True', 'use_colors': 'True', 'use_experimental_parser': 'False', 'no_print': 'None', 'quiet': 'False', 'empty': 'False', 'log_format': 'default', 'introspect': 'True', 'warn_error_options': 'WarnErrorOptions(include=[], exclude=[])', 'invocation_command': 'dbt run --select +demographic --full-refresh', 'target_path': 'None', 'static_parser': 'True', 'send_anonymous_usage_stats': 'True'}
[0m10:57:34.778110 [error] [MainThread]: Encountered an error:
Runtime Error
  No dbt_project.yml found at expected path C:\Users\zhma\Projects\ammi\dbt_project.yml
  Verify that each entry within packages.yml (and their transitive dependencies) contains a file named dbt_project.yml
  
[0m10:57:34.778110 [debug] [MainThread]: Command `dbt run` failed at 10:57:34.778110 after 0.15 seconds
[0m10:57:34.778110 [debug] [MainThread]: Sending event: {'category': 'dbt', 'action': 'invocation', 'label': 'end', 'context': [<snowplow_tracker.self_describing_json.SelfDescribingJson object at 0x000002391EF6F140>, <snowplow_tracker.self_describing_json.SelfDescribingJson object at 0x000002391F729C40>, <snowplow_tracker.self_describing_json.SelfDescribingJson object at 0x0000023919857170>]}
[0m10:57:34.778110 [debug] [MainThread]: Flushing usage events
[0m10:57:35.148761 [debug] [MainThread]: An error was encountered while trying to flush usage events
[0m13:49:05.379238 [debug] [MainThread]: Sending event: {'category': 'dbt', 'action': 'invocation', 'label': 'start', 'context': [<snowplow_tracker.self_describing_json.SelfDescribingJson object at 0x0000028296AE7470>, <snowplow_tracker.self_describing_json.SelfDescribingJson object at 0x0000028296396450>, <snowplow_tracker.self_describing_json.SelfDescribingJson object at 0x0000028296AE6EA0>]}


============================== 13:49:05.379238 | 03fb8d9e-b0c3-48e6-9407-ee91231cf13a ==============================
[0m13:49:05.379238 [info ] [MainThread]: Running with dbt=1.9.4
[0m13:49:05.379238 [debug] [MainThread]: running dbt with arguments {'printer_width': '80', 'indirect_selection': 'eager', 'write_json': 'True', 'log_cache_events': 'False', 'partial_parse': 'True', 'cache_selected_only': 'False', 'warn_error': 'None', 'version_check': 'True', 'profiles_dir': 'C:\\Users\\zhma\\.dbt', 'log_path': 'logs', 'fail_fast': 'False', 'debug': 'False', 'use_colors': 'True', 'use_experimental_parser': 'False', 'no_print': 'None', 'quiet': 'False', 'empty': 'None', 'warn_error_options': 'WarnErrorOptions(include=[], exclude=[])', 'introspect': 'True', 'invocation_command': 'dbt docs generate', 'log_format': 'default', 'target_path': 'None', 'static_parser': 'True', 'send_anonymous_usage_stats': 'True'}
[0m13:49:05.379238 [error] [MainThread]: Encountered an error:
Runtime Error
  No dbt_project.yml found at expected path C:\Users\zhma\Projects\ammi\dbt_project.yml
  Verify that each entry within packages.yml (and their transitive dependencies) contains a file named dbt_project.yml
  
[0m13:49:05.394864 [debug] [MainThread]: Command `dbt docs generate` failed at 13:49:05.394864 after 0.11 seconds
[0m13:49:05.394864 [debug] [MainThread]: Sending event: {'category': 'dbt', 'action': 'invocation', 'label': 'end', 'context': [<snowplow_tracker.self_describing_json.SelfDescribingJson object at 0x0000028296396450>, <snowplow_tracker.self_describing_json.SelfDescribingJson object at 0x0000028296AE6EA0>, <snowplow_tracker.self_describing_json.SelfDescribingJson object at 0x0000028296AE6FF0>]}
[0m13:49:05.394864 [debug] [MainThread]: Flushing usage events
[0m13:49:05.780151 [debug] [MainThread]: An error was encountered while trying to flush usage events
[0m14:47:07.628053 [debug] [MainThread]: Sending event: {'category': 'dbt', 'action': 'invocation', 'label': 'start', 'context': [<snowplow_tracker.self_describing_json.SelfDescribingJson object at 0x000002711E849C10>, <snowplow_tracker.self_describing_json.SelfDescribingJson object at 0x000002711E0D1D60>, <snowplow_tracker.self_describing_json.SelfDescribingJson object at 0x000002711E0F5340>]}


============================== 14:47:07.643677 | 99fa143c-b5bf-43c1-bc4c-56c5e95a804d ==============================
[0m14:47:07.643677 [info ] [MainThread]: Running with dbt=1.9.4
[0m14:47:07.643677 [debug] [MainThread]: running dbt with arguments {'printer_width': '80', 'indirect_selection': 'eager', 'write_json': 'True', 'log_cache_events': 'False', 'partial_parse': 'True', 'cache_selected_only': 'False', 'profiles_dir': 'C:\\Users\\zhma\\.dbt', 'debug': 'False', 'fail_fast': 'False', 'log_path': 'logs', 'warn_error': 'None', 'version_check': 'True', 'use_colors': 'True', 'use_experimental_parser': 'False', 'empty': 'None', 'quiet': 'False', 'no_print': 'None', 'warn_error_options': 'WarnErrorOptions(include=[], exclude=[])', 'introspect': 'True', 'invocation_command': 'dbt run-operation generate_model_yaml --args {model_names: [rpt_preeclampsia]}', 'static_parser': 'True', 'target_path': 'None', 'log_format': 'default', 'send_anonymous_usage_stats': 'True'}
[0m14:47:07.643677 [error] [MainThread]: Encountered an error:
Runtime Error
  No dbt_project.yml found at expected path C:\Users\zhma\Projects\ammi\dbt_project.yml
  Verify that each entry within packages.yml (and their transitive dependencies) contains a file named dbt_project.yml
  
[0m14:47:07.643677 [debug] [MainThread]: Command `dbt run-operation` failed at 14:47:07.643677 after 0.12 seconds
[0m14:47:07.643677 [debug] [MainThread]: Sending event: {'category': 'dbt', 'action': 'invocation', 'label': 'end', 'context': [<snowplow_tracker.self_describing_json.SelfDescribingJson object at 0x000002711E95ABA0>, <snowplow_tracker.self_describing_json.SelfDescribingJson object at 0x000002711E7FFA40>, <snowplow_tracker.self_describing_json.SelfDescribingJson object at 0x000002711E937230>]}
[0m14:47:07.643677 [debug] [MainThread]: Flushing usage events
[0m14:47:07.988493 [debug] [MainThread]: An error was encountered while trying to flush usage events
[0m09:19:35.260843 [debug] [MainThread]: Sending event: {'category': 'dbt', 'action': 'invocation', 'label': 'start', 'context': [<snowplow_tracker.self_describing_json.SelfDescribingJson object at 0x000001FAD1821310>, <snowplow_tracker.self_describing_json.SelfDescribingJson object at 0x000001FAD4C6BBF0>, <snowplow_tracker.self_describing_json.SelfDescribingJson object at 0x000001FAD3122B40>]}


============================== 09:19:35.260843 | 9c6b2f6a-259a-451d-9616-b8256e724451 ==============================
[0m09:19:35.260843 [info ] [MainThread]: Running with dbt=1.9.4
[0m09:19:35.260843 [debug] [MainThread]: running dbt with arguments {'printer_width': '80', 'indirect_selection': 'eager', 'write_json': 'True', 'log_cache_events': 'False', 'partial_parse': 'True', 'cache_selected_only': 'False', 'warn_error': 'None', 'fail_fast': 'False', 'version_check': 'True', 'log_path': 'logs', 'profiles_dir': 'C:\\Users\\zhma\\.dbt', 'debug': 'False', 'use_colors': 'True', 'use_experimental_parser': 'False', 'empty': 'False', 'quiet': 'False', 'no_print': 'None', 'log_format': 'default', 'introspect': 'True', 'warn_error_options': 'WarnErrorOptions(include=[], exclude=[])', 'invocation_command': 'dbt run --select +int_mental_cat', 'target_path': 'None', 'static_parser': 'True', 'send_anonymous_usage_stats': 'True'}
[0m09:19:35.260843 [error] [MainThread]: Encountered an error:
Runtime Error
  No dbt_project.yml found at expected path C:\Users\zhma\Projects\ammi\dbt_project.yml
  Verify that each entry within packages.yml (and their transitive dependencies) contains a file named dbt_project.yml
  
[0m09:19:35.260843 [debug] [MainThread]: Command `dbt run` failed at 09:19:35.260843 after 0.19 seconds
[0m09:19:35.260843 [debug] [MainThread]: Sending event: {'category': 'dbt', 'action': 'invocation', 'label': 'end', 'context': [<snowplow_tracker.self_describing_json.SelfDescribingJson object at 0x000001FAD52626F0>, <snowplow_tracker.self_describing_json.SelfDescribingJson object at 0x000001FAD4245CD0>, <snowplow_tracker.self_describing_json.SelfDescribingJson object at 0x000001FAD4244B00>]}
[0m09:19:35.260843 [debug] [MainThread]: Flushing usage events
[0m09:19:35.660576 [debug] [MainThread]: An error was encountered while trying to flush usage events
[0m15:19:43.244007 [debug] [MainThread]: Sending event: {'category': 'dbt', 'action': 'invocation', 'label': 'start', 'context': [<snowplow_tracker.self_describing_json.SelfDescribingJson object at 0x000001CF7ED0D9D0>, <snowplow_tracker.self_describing_json.SelfDescribingJson object at 0x000001CF0140CC80>, <snowplow_tracker.self_describing_json.SelfDescribingJson object at 0x000001CF0100AB70>]}


============================== 15:19:43.257126 | 7c2103e1-3e9e-4df8-b41d-b33b96efba85 ==============================
[0m15:19:43.257126 [info ] [MainThread]: Running with dbt=1.9.4
[0m15:19:43.257126 [debug] [MainThread]: running dbt with arguments {'printer_width': '80', 'indirect_selection': 'eager', 'log_cache_events': 'False', 'write_json': 'True', 'partial_parse': 'True', 'cache_selected_only': 'False', 'profiles_dir': 'C:\\Users\\zhma\\.dbt', 'fail_fast': 'False', 'warn_error': 'None', 'log_path': 'logs', 'debug': 'False', 'version_check': 'True', 'use_colors': 'True', 'use_experimental_parser': 'False', 'no_print': 'None', 'quiet': 'False', 'empty': 'False', 'warn_error_options': 'WarnErrorOptions(include=[], exclude=[])', 'static_parser': 'True', 'log_format': 'default', 'invocation_command': 'dbt run --select +int_preeclampsia__chronic_bp_cat', 'target_path': 'None', 'introspect': 'True', 'send_anonymous_usage_stats': 'True'}
[0m15:19:43.257126 [error] [MainThread]: Encountered an error:
Runtime Error
  No dbt_project.yml found at expected path C:\Users\zhma\Projects\ammi\dbt_project.yml
  Verify that each entry within packages.yml (and their transitive dependencies) contains a file named dbt_project.yml
  
[0m15:19:43.260637 [debug] [MainThread]: Command `dbt run` failed at 15:19:43.260637 after 0.14 seconds
[0m15:19:43.260637 [debug] [MainThread]: Sending event: {'category': 'dbt', 'action': 'invocation', 'label': 'end', 'context': [<snowplow_tracker.self_describing_json.SelfDescribingJson object at 0x000001CF01336A80>, <snowplow_tracker.self_describing_json.SelfDescribingJson object at 0x000001CF7ED0D9D0>, <snowplow_tracker.self_describing_json.SelfDescribingJson object at 0x000001CF016761E0>]}
[0m15:19:43.260637 [debug] [MainThread]: Flushing usage events
[0m15:19:43.598214 [debug] [MainThread]: An error was encountered while trying to flush usage events
[0m10:57:09.065748 [debug] [MainThread]: Sending event: {'category': 'dbt', 'action': 'invocation', 'label': 'start', 'context': [<snowplow_tracker.self_describing_json.SelfDescribingJson object at 0x000001C8289B5940>, <snowplow_tracker.self_describing_json.SelfDescribingJson object at 0x000001C82AEB9580>, <snowplow_tracker.self_describing_json.SelfDescribingJson object at 0x000001C828E159D0>]}


============================== 10:57:09.069747 | 12e58c4f-0e5e-4391-9886-0a50e979a8aa ==============================
[0m10:57:09.069747 [info ] [MainThread]: Running with dbt=1.9.4
[0m10:57:09.071250 [debug] [MainThread]: running dbt with arguments {'printer_width': '80', 'indirect_selection': 'eager', 'write_json': 'True', 'log_cache_events': 'False', 'partial_parse': 'True', 'cache_selected_only': 'False', 'warn_error': 'None', 'version_check': 'True', 'debug': 'False', 'log_path': 'logs', 'fail_fast': 'False', 'profiles_dir': 'C:\\Users\\zhma\\.dbt', 'use_colors': 'True', 'use_experimental_parser': 'False', 'empty': 'None', 'quiet': 'False', 'no_print': 'None', 'log_format': 'default', 'invocation_command': 'dbt run-operation generate_model_yaml --args {model_names: [int_cohort]}', 'warn_error_options': 'WarnErrorOptions(include=[], exclude=[])', 'introspect': 'True', 'target_path': 'None', 'static_parser': 'True', 'send_anonymous_usage_stats': 'True'}
[0m10:57:09.071250 [error] [MainThread]: Encountered an error:
Runtime Error
  No dbt_project.yml found at expected path C:\Users\zhma\Projects\ammi\dbt_project.yml
  Verify that each entry within packages.yml (and their transitive dependencies) contains a file named dbt_project.yml
  
[0m10:57:09.072255 [debug] [MainThread]: Command `dbt run-operation` failed at 10:57:09.072255 after 0.13 seconds
[0m10:57:09.073256 [debug] [MainThread]: Sending event: {'category': 'dbt', 'action': 'invocation', 'label': 'end', 'context': [<snowplow_tracker.self_describing_json.SelfDescribingJson object at 0x000001C82B707E90>, <snowplow_tracker.self_describing_json.SelfDescribingJson object at 0x000001C8289B5940>, <snowplow_tracker.self_describing_json.SelfDescribingJson object at 0x000001C82B0E4C80>]}
[0m10:57:09.073808 [debug] [MainThread]: Flushing usage events
[0m10:57:09.476341 [debug] [MainThread]: An error was encountered while trying to flush usage events
[0m11:22:10.049053 [debug] [MainThread]: Sending event: {'category': 'dbt', 'action': 'invocation', 'label': 'start', 'context': [<snowplow_tracker.self_describing_json.SelfDescribingJson object at 0x000001B402C65A60>, <snowplow_tracker.self_describing_json.SelfDescribingJson object at 0x000001B404E19700>, <snowplow_tracker.self_describing_json.SelfDescribingJson object at 0x000001B404E1B560>]}


============================== 11:22:10.057229 | 8df23fec-4aee-4935-8c89-72e9883d9738 ==============================
[0m11:22:10.057229 [info ] [MainThread]: Running with dbt=1.9.4
[0m11:22:10.057229 [debug] [MainThread]: running dbt with arguments {'printer_width': '80', 'indirect_selection': 'eager', 'write_json': 'True', 'log_cache_events': 'False', 'partial_parse': 'True', 'cache_selected_only': 'False', 'warn_error': 'None', 'fail_fast': 'False', 'debug': 'False', 'log_path': 'logs', 'profiles_dir': 'C:\\Users\\zhma\\.dbt', 'version_check': 'True', 'use_colors': 'True', 'use_experimental_parser': 'False', 'empty': 'False', 'quiet': 'False', 'no_print': 'None', 'warn_error_options': 'WarnErrorOptions(include=[], exclude=[])', 'static_parser': 'True', 'introspect': 'True', 'invocation_command': 'dbt run --full-refresh', 'target_path': 'None', 'log_format': 'default', 'send_anonymous_usage_stats': 'True'}
[0m11:22:10.057229 [error] [MainThread]: Encountered an error:
Runtime Error
  No dbt_project.yml found at expected path C:\Users\zhma\Projects\ammi\dbt_project.yml
  Verify that each entry within packages.yml (and their transitive dependencies) contains a file named dbt_project.yml
  
[0m11:22:10.057229 [debug] [MainThread]: Command `dbt run` failed at 11:22:10.057229 after 0.14 seconds
[0m11:22:10.057229 [debug] [MainThread]: Sending event: {'category': 'dbt', 'action': 'invocation', 'label': 'end', 'context': [<snowplow_tracker.self_describing_json.SelfDescribingJson object at 0x000001B4054B5E80>, <snowplow_tracker.self_describing_json.SelfDescribingJson object at 0x000001B402C65A60>, <snowplow_tracker.self_describing_json.SelfDescribingJson object at 0x000001B47F02B4D0>]}
[0m11:22:10.057229 [debug] [MainThread]: Flushing usage events
[0m11:22:10.364279 [debug] [MainThread]: An error was encountered while trying to flush usage events
[0m13:56:39.020282 [debug] [MainThread]: Sending event: {'category': 'dbt', 'action': 'invocation', 'label': 'start', 'context': [<snowplow_tracker.self_describing_json.SelfDescribingJson object at 0x000002690D6BE7B0>, <snowplow_tracker.self_describing_json.SelfDescribingJson object at 0x000002690B58B200>, <snowplow_tracker.self_describing_json.SelfDescribingJson object at 0x000002690ACBB7A0>]}


============================== 13:56:39.023296 | 4d6ef353-aa2f-483a-b419-511751864aa4 ==============================
[0m13:56:39.023296 [info ] [MainThread]: Running with dbt=1.9.4
[0m13:56:39.023610 [debug] [MainThread]: running dbt with arguments {'printer_width': '80', 'indirect_selection': 'eager', 'write_json': 'True', 'log_cache_events': 'False', 'partial_parse': 'True', 'cache_selected_only': 'False', 'warn_error': 'None', 'version_check': 'True', 'profiles_dir': 'C:\\Users\\zhma\\.dbt', 'log_path': 'logs', 'debug': 'False', 'fail_fast': 'False', 'use_colors': 'True', 'use_experimental_parser': 'False', 'no_print': 'None', 'quiet': 'False', 'empty': 'False', 'log_format': 'default', 'static_parser': 'True', 'invocation_command': 'dbt run --select +int_preeclampsia_chronic_bp_cat', 'introspect': 'True', 'target_path': 'None', 'warn_error_options': 'WarnErrorOptions(include=[], exclude=[])', 'send_anonymous_usage_stats': 'True'}
[0m13:56:39.023610 [error] [MainThread]: Encountered an error:
Runtime Error
  No dbt_project.yml found at expected path C:\Users\zhma\Projects\ammi\dbt_project.yml
  Verify that each entry within packages.yml (and their transitive dependencies) contains a file named dbt_project.yml
  
[0m13:56:39.024815 [debug] [MainThread]: Command `dbt run` failed at 13:56:39.024815 after 0.13 seconds
[0m13:56:39.025839 [debug] [MainThread]: Sending event: {'category': 'dbt', 'action': 'invocation', 'label': 'end', 'context': [<snowplow_tracker.self_describing_json.SelfDescribingJson object at 0x000002690DE2C9E0>, <snowplow_tracker.self_describing_json.SelfDescribingJson object at 0x000002690E1E80E0>, <snowplow_tracker.self_describing_json.SelfDescribingJson object at 0x000002690D80EBA0>]}
[0m13:56:39.025839 [debug] [MainThread]: Flushing usage events
[0m13:56:39.354186 [debug] [MainThread]: An error was encountered while trying to flush usage events
[0m14:17:59.695789 [debug] [MainThread]: Sending event: {'category': 'dbt', 'action': 'invocation', 'label': 'start', 'context': [<snowplow_tracker.self_describing_json.SelfDescribingJson object at 0x000001B3755ED7C0>, <snowplow_tracker.self_describing_json.SelfDescribingJson object at 0x000001B378209C40>, <snowplow_tracker.self_describing_json.SelfDescribingJson object at 0x000001B3782080B0>]}


============================== 14:17:59.699358 | fd2f8b5b-ac20-47e5-b0f5-2c9a57a46580 ==============================
[0m14:17:59.699358 [info ] [MainThread]: Running with dbt=1.9.4
[0m14:17:59.699358 [debug] [MainThread]: running dbt with arguments {'printer_width': '80', 'indirect_selection': 'eager', 'log_cache_events': 'False', 'write_json': 'True', 'partial_parse': 'True', 'cache_selected_only': 'False', 'warn_error': 'None', 'fail_fast': 'False', 'debug': 'False', 'log_path': 'logs', 'profiles_dir': 'C:\\Users\\zhma\\.dbt', 'version_check': 'True', 'use_colors': 'True', 'use_experimental_parser': 'False', 'no_print': 'None', 'quiet': 'False', 'empty': 'None', 'warn_error_options': 'WarnErrorOptions(include=[], exclude=[])', 'introspect': 'True', 'static_parser': 'True', 'log_format': 'default', 'target_path': 'None', 'invocation_command': 'dbt docs serve', 'send_anonymous_usage_stats': 'True'}
[0m14:17:59.699358 [error] [MainThread]: Encountered an error:
Runtime Error
  No dbt_project.yml found at expected path C:\Users\zhma\Projects\ammi\dbt_project.yml
  Verify that each entry within packages.yml (and their transitive dependencies) contains a file named dbt_project.yml
  
[0m14:17:59.704073 [debug] [MainThread]: Command `dbt docs serve` failed at 14:17:59.704073 after 0.19 seconds
[0m14:17:59.704073 [debug] [MainThread]: Sending event: {'category': 'dbt', 'action': 'invocation', 'label': 'end', 'context': [<snowplow_tracker.self_describing_json.SelfDescribingJson object at 0x000001B3782F78C0>, <snowplow_tracker.self_describing_json.SelfDescribingJson object at 0x000001B377DF18E0>, <snowplow_tracker.self_describing_json.SelfDescribingJson object at 0x000001B377F6A510>]}
[0m14:17:59.704073 [debug] [MainThread]: Flushing usage events
[0m14:18:00.148288 [debug] [MainThread]: An error was encountered while trying to flush usage events
[0m11:00:15.479800 [debug] [MainThread]: Sending event: {'category': 'dbt', 'action': 'invocation', 'label': 'start', 'context': [<snowplow_tracker.self_describing_json.SelfDescribingJson object at 0x000001F3A62574D0>, <snowplow_tracker.self_describing_json.SelfDescribingJson object at 0x000001F3A8AC7590>, <snowplow_tracker.self_describing_json.SelfDescribingJson object at 0x000001F3A88C5A00>]}


============================== 11:00:15.483826 | a0f4d7d7-1a2d-4d81-bbf5-c7e9f2c6f72b ==============================
[0m11:00:15.483826 [info ] [MainThread]: Running with dbt=1.9.4
[0m11:00:15.484831 [debug] [MainThread]: running dbt with arguments {'printer_width': '80', 'indirect_selection': 'eager', 'log_cache_events': 'False', 'write_json': 'True', 'partial_parse': 'True', 'cache_selected_only': 'False', 'profiles_dir': 'C:\\Users\\zhma\\.dbt', 'version_check': 'True', 'fail_fast': 'False', 'log_path': 'logs', 'debug': 'False', 'warn_error': 'None', 'use_colors': 'True', 'use_experimental_parser': 'False', 'no_print': 'None', 'quiet': 'False', 'empty': 'False', 'log_format': 'default', 'introspect': 'True', 'static_parser': 'True', 'warn_error_options': 'WarnErrorOptions(include=[], exclude=[])', 'target_path': 'None', 'invocation_command': 'dbt run', 'send_anonymous_usage_stats': 'True'}
[0m11:00:15.484831 [error] [MainThread]: Encountered an error:
Runtime Error
  No dbt_project.yml found at expected path C:\Users\zhma\Projects\ammi\dbt_project.yml
  Verify that each entry within packages.yml (and their transitive dependencies) contains a file named dbt_project.yml
  
[0m11:00:15.485830 [debug] [MainThread]: Command `dbt run` failed at 11:00:15.485830 after 0.12 seconds
[0m11:00:15.485830 [debug] [MainThread]: Sending event: {'category': 'dbt', 'action': 'invocation', 'label': 'end', 'context': [<snowplow_tracker.self_describing_json.SelfDescribingJson object at 0x000001F3A90148C0>, <snowplow_tracker.self_describing_json.SelfDescribingJson object at 0x000001F3A84A68A0>, <snowplow_tracker.self_describing_json.SelfDescribingJson object at 0x000001F3A84A4DA0>]}
[0m11:00:15.486832 [debug] [MainThread]: Flushing usage events
[0m11:00:15.716315 [debug] [MainThread]: An error was encountered while trying to flush usage events
[0m13:21:58.707092 [debug] [MainThread]: Sending event: {'category': 'dbt', 'action': 'invocation', 'label': 'start', 'context': [<snowplow_tracker.self_describing_json.SelfDescribingJson object at 0x000002172C149940>, <snowplow_tracker.self_describing_json.SelfDescribingJson object at 0x000002172E8687A0>, <snowplow_tracker.self_describing_json.SelfDescribingJson object at 0x000002172E9EE4B0>]}


============================== 13:21:58.707092 | e1cbbef0-5856-47aa-bd33-83c88128b44a ==============================
[0m13:21:58.707092 [info ] [MainThread]: Running with dbt=1.9.4
[0m13:21:58.707092 [debug] [MainThread]: running dbt with arguments {'printer_width': '80', 'indirect_selection': 'eager', 'write_json': 'True', 'log_cache_events': 'False', 'partial_parse': 'True', 'cache_selected_only': 'False', 'warn_error': 'None', 'fail_fast': 'False', 'debug': 'False', 'log_path': 'logs', 'profiles_dir': 'C:\\Users\\zhma\\.dbt', 'version_check': 'True', 'use_colors': 'True', 'use_experimental_parser': 'False', 'empty': 'False', 'quiet': 'False', 'no_print': 'None', 'log_format': 'default', 'static_parser': 'True', 'introspect': 'True', 'invocation_command': 'dbt run --select int_mental_cat', 'target_path': 'None', 'warn_error_options': 'WarnErrorOptions(include=[], exclude=[])', 'send_anonymous_usage_stats': 'True'}
[0m13:21:58.707092 [error] [MainThread]: Encountered an error:
Runtime Error
  No dbt_project.yml found at expected path C:\Users\zhma\Projects\ammi\dbt_project.yml
  Verify that each entry within packages.yml (and their transitive dependencies) contains a file named dbt_project.yml
  
[0m13:21:58.707092 [debug] [MainThread]: Command `dbt run` failed at 13:21:58.707092 after 0.12 seconds
[0m13:21:58.707092 [debug] [MainThread]: Sending event: {'category': 'dbt', 'action': 'invocation', 'label': 'end', 'context': [<snowplow_tracker.self_describing_json.SelfDescribingJson object at 0x000002172E8687A0>, <snowplow_tracker.self_describing_json.SelfDescribingJson object at 0x000002172EAADEE0>, <snowplow_tracker.self_describing_json.SelfDescribingJson object at 0x000002172EE96D80>]}
[0m13:21:58.707092 [debug] [MainThread]: Flushing usage events
[0m13:21:59.060235 [debug] [MainThread]: An error was encountered while trying to flush usage events
